2024-10-09 12:07:29,371 - ERROR    ->  6  -  1  -  1   - Failed to get 'cp, province, locality'.
Traceback (most recent call last):
  File "/home/miguel/coding-projects/ScrapingFincasHacienda/env/lib/python3.12/site-packages/urllib3/connection.py", line 198, in _new_conn
    sock = connection.create_connection(
           ^^^^^^^^^^^^^^^^^^^^^^^^^^^^^
  File "/home/miguel/coding-projects/ScrapingFincasHacienda/env/lib/python3.12/site-packages/urllib3/util/connection.py", line 85, in create_connection
    raise err
  File "/home/miguel/coding-projects/ScrapingFincasHacienda/env/lib/python3.12/site-packages/urllib3/util/connection.py", line 73, in create_connection
    sock.connect(sa)
ConnectionRefusedError: [Errno 111] Connection refused

The above exception was the direct cause of the following exception:

Traceback (most recent call last):
  File "/home/miguel/coding-projects/ScrapingFincasHacienda/env/lib/python3.12/site-packages/urllib3/connectionpool.py", line 793, in urlopen
    response = self._make_request(
               ^^^^^^^^^^^^^^^^^^^
  File "/home/miguel/coding-projects/ScrapingFincasHacienda/env/lib/python3.12/site-packages/urllib3/connectionpool.py", line 496, in _make_request
    conn.request(
  File "/home/miguel/coding-projects/ScrapingFincasHacienda/env/lib/python3.12/site-packages/urllib3/connection.py", line 400, in request
    self.endheaders()
  File "/usr/lib/python3.12/http/client.py", line 1331, in endheaders
    self._send_output(message_body, encode_chunked=encode_chunked)
  File "/usr/lib/python3.12/http/client.py", line 1091, in _send_output
    self.send(msg)
  File "/usr/lib/python3.12/http/client.py", line 1035, in send
    self.connect()
  File "/home/miguel/coding-projects/ScrapingFincasHacienda/env/lib/python3.12/site-packages/urllib3/connection.py", line 238, in connect
    self.sock = self._new_conn()
                ^^^^^^^^^^^^^^^^
  File "/home/miguel/coding-projects/ScrapingFincasHacienda/env/lib/python3.12/site-packages/urllib3/connection.py", line 213, in _new_conn
    raise NewConnectionError(
urllib3.exceptions.NewConnectionError: <urllib3.connection.HTTPConnection object at 0x702d1cae15e0>: Failed to establish a new connection: [Errno 111] Connection refused

The above exception was the direct cause of the following exception:

Traceback (most recent call last):
  File "/home/miguel/coding-projects/ScrapingFincasHacienda/scrapingFincasHacienda/Correos/correos.py", line 62, in get_data
    self.__search()
  File "/home/miguel/coding-projects/ScrapingFincasHacienda/scrapingFincasHacienda/Correos/correos.py", line 116, in __search
    search_input = self.find_element(
                   ^^^^^^^^^^^^^^^^^^
  File "/home/miguel/coding-projects/ScrapingFincasHacienda/env/lib/python3.12/site-packages/selenium/webdriver/remote/webdriver.py", line 748, in find_element
    return self.execute(Command.FIND_ELEMENT, {"using": by, "value": value})["value"]
           ^^^^^^^^^^^^^^^^^^^^^^^^^^^^^^^^^^^^^^^^^^^^^^^^^^^^^^^^^^^^^^^^^
  File "/home/miguel/coding-projects/ScrapingFincasHacienda/env/lib/python3.12/site-packages/selenium/webdriver/remote/webdriver.py", line 352, in execute
    response = self.command_executor.execute(driver_command, params)
               ^^^^^^^^^^^^^^^^^^^^^^^^^^^^^^^^^^^^^^^^^^^^^^^^^^^^^
  File "/home/miguel/coding-projects/ScrapingFincasHacienda/env/lib/python3.12/site-packages/selenium/webdriver/remote/remote_connection.py", line 306, in execute
    return self._request(command_info[0], url, body=data)
           ^^^^^^^^^^^^^^^^^^^^^^^^^^^^^^^^^^^^^^^^^^^^^^
  File "/home/miguel/coding-projects/ScrapingFincasHacienda/env/lib/python3.12/site-packages/selenium/webdriver/remote/remote_connection.py", line 326, in _request
    response = self._conn.request(method, url, body=body, headers=headers)
               ^^^^^^^^^^^^^^^^^^^^^^^^^^^^^^^^^^^^^^^^^^^^^^^^^^^^^^^^^^^
  File "/home/miguel/coding-projects/ScrapingFincasHacienda/env/lib/python3.12/site-packages/urllib3/_request_methods.py", line 144, in request
    return self.request_encode_body(
           ^^^^^^^^^^^^^^^^^^^^^^^^^
  File "/home/miguel/coding-projects/ScrapingFincasHacienda/env/lib/python3.12/site-packages/urllib3/_request_methods.py", line 279, in request_encode_body
    return self.urlopen(method, url, **extra_kw)
           ^^^^^^^^^^^^^^^^^^^^^^^^^^^^^^^^^^^^^
  File "/home/miguel/coding-projects/ScrapingFincasHacienda/env/lib/python3.12/site-packages/urllib3/poolmanager.py", line 444, in urlopen
    response = conn.urlopen(method, u.request_uri, **kw)
               ^^^^^^^^^^^^^^^^^^^^^^^^^^^^^^^^^^^^^^^^^
  File "/home/miguel/coding-projects/ScrapingFincasHacienda/env/lib/python3.12/site-packages/urllib3/connectionpool.py", line 877, in urlopen
    return self.urlopen(
           ^^^^^^^^^^^^^
  File "/home/miguel/coding-projects/ScrapingFincasHacienda/env/lib/python3.12/site-packages/urllib3/connectionpool.py", line 877, in urlopen
    return self.urlopen(
           ^^^^^^^^^^^^^
  File "/home/miguel/coding-projects/ScrapingFincasHacienda/env/lib/python3.12/site-packages/urllib3/connectionpool.py", line 877, in urlopen
    return self.urlopen(
           ^^^^^^^^^^^^^
  File "/home/miguel/coding-projects/ScrapingFincasHacienda/env/lib/python3.12/site-packages/urllib3/connectionpool.py", line 847, in urlopen
    retries = retries.increment(
              ^^^^^^^^^^^^^^^^^^
  File "/home/miguel/coding-projects/ScrapingFincasHacienda/env/lib/python3.12/site-packages/urllib3/util/retry.py", line 515, in increment
    raise MaxRetryError(_pool, url, reason) from reason  # type: ignore[arg-type]
    ^^^^^^^^^^^^^^^^^^^^^^^^^^^^^^^^^^^^^^^^^^^^^^^^^^^
urllib3.exceptions.MaxRetryError: HTTPConnectionPool(host='localhost', port=36825): Max retries exceeded with url: /session/e3d0e69ea55c4188e422e8dcb317c5c4/element (Caused by NewConnectionError('<urllib3.connection.HTTPConnection object at 0x702d1cae15e0>: Failed to establish a new connection: [Errno 111] Connection refused'))
2024-10-09 12:08:33,852 - ERROR    ->  16 -  1  -  1   - Failed to get data from land '16102A502000230000QX'
Traceback (most recent call last):
  File "/home/miguel/coding-projects/ScrapingFincasHacienda/scrapingFincasHacienda/Catastro/catastro.py", line 81, in get_data
    self.__search()
  File "/home/miguel/coding-projects/ScrapingFincasHacienda/scrapingFincasHacienda/Catastro/catastro.py", line 132, in __search
    self.__close_cookies()
  File "/home/miguel/coding-projects/ScrapingFincasHacienda/scrapingFincasHacienda/Catastro/catastro.py", line 298, in __close_cookies
    button_cookie.click()
    ^^^^^^^^^^^^^^^^^^^
AttributeError: 'NoneType' object has no attribute 'click'
2024-10-09 12:08:35,863 - ERROR    ->  16 -  2  -  1   - Failed to get data from land '16102A502000490000QK'
Traceback (most recent call last):
  File "/home/miguel/coding-projects/ScrapingFincasHacienda/scrapingFincasHacienda/Catastro/catastro.py", line 81, in get_data
    self.__search()
  File "/home/miguel/coding-projects/ScrapingFincasHacienda/scrapingFincasHacienda/Catastro/catastro.py", line 132, in __search
    self.__close_cookies()
  File "/home/miguel/coding-projects/ScrapingFincasHacienda/scrapingFincasHacienda/Catastro/catastro.py", line 294, in __close_cookies
    button_cookie = self.find_element(
                    ^^^^^^^^^^^^^^^^^^
  File "/home/miguel/coding-projects/ScrapingFincasHacienda/env/lib/python3.12/site-packages/selenium/webdriver/remote/webdriver.py", line 748, in find_element
    return self.execute(Command.FIND_ELEMENT, {"using": by, "value": value})["value"]
           ^^^^^^^^^^^^^^^^^^^^^^^^^^^^^^^^^^^^^^^^^^^^^^^^^^^^^^^^^^^^^^^^^
  File "/home/miguel/coding-projects/ScrapingFincasHacienda/env/lib/python3.12/site-packages/selenium/webdriver/remote/webdriver.py", line 354, in execute
    self.error_handler.check_response(response)
  File "/home/miguel/coding-projects/ScrapingFincasHacienda/env/lib/python3.12/site-packages/selenium/webdriver/remote/errorhandler.py", line 229, in check_response
    raise exception_class(message, screen, stacktrace)
selenium.common.exceptions.NoSuchWindowException: Message: no such window: target window already closed
from unknown error: web view not found
  (Session info: chrome=128.0.6613.113)
Stacktrace:
#0 0x6161dc18a2da <unknown>
#1 0x6161dbe58200 <unknown>
#2 0x6161dbe2da1f <unknown>
#3 0x6161dbed4eed <unknown>
#4 0x6161dbeea6a9 <unknown>
#5 0x6161dbecc673 <unknown>
#6 0x6161dbe9a473 <unknown>
#7 0x6161dbe9b47e <unknown>
#8 0x6161dc1510db <unknown>
#9 0x6161dc155071 <unknown>
#10 0x6161dc13d9d5 <unknown>
#11 0x6161dc155bf2 <unknown>
#12 0x6161dc122b6f <unknown>
#13 0x6161dc179248 <unknown>
#14 0x6161dc179417 <unknown>
#15 0x6161dc1890cc <unknown>
#16 0x78d986ae939d <unknown>
#17 0x78d986b6e49c <unknown>

2024-10-09 12:08:38,631 - ERROR    ->  16 -  3  -  1   - Failed to get data from land '16102A502000960000QU'
Traceback (most recent call last):
  File "/home/miguel/coding-projects/ScrapingFincasHacienda/scrapingFincasHacienda/Catastro/catastro.py", line 81, in get_data
    self.__search()
  File "/home/miguel/coding-projects/ScrapingFincasHacienda/scrapingFincasHacienda/Catastro/catastro.py", line 132, in __search
    self.__close_cookies()
  File "/home/miguel/coding-projects/ScrapingFincasHacienda/scrapingFincasHacienda/Catastro/catastro.py", line 294, in __close_cookies
    button_cookie = self.find_element(
                    ^^^^^^^^^^^^^^^^^^
  File "/home/miguel/coding-projects/ScrapingFincasHacienda/env/lib/python3.12/site-packages/selenium/webdriver/remote/webdriver.py", line 748, in find_element
    return self.execute(Command.FIND_ELEMENT, {"using": by, "value": value})["value"]
           ^^^^^^^^^^^^^^^^^^^^^^^^^^^^^^^^^^^^^^^^^^^^^^^^^^^^^^^^^^^^^^^^^
  File "/home/miguel/coding-projects/ScrapingFincasHacienda/env/lib/python3.12/site-packages/selenium/webdriver/remote/webdriver.py", line 354, in execute
    self.error_handler.check_response(response)
  File "/home/miguel/coding-projects/ScrapingFincasHacienda/env/lib/python3.12/site-packages/selenium/webdriver/remote/errorhandler.py", line 229, in check_response
    raise exception_class(message, screen, stacktrace)
selenium.common.exceptions.NoSuchWindowException: Message: no such window: target window already closed
from unknown error: web view not found
  (Session info: chrome=128.0.6613.113)
Stacktrace:
#0 0x5b8ffdc942da <unknown>
#1 0x5b8ffd962200 <unknown>
#2 0x5b8ffd937a1f <unknown>
#3 0x5b8ffd9deeed <unknown>
#4 0x5b8ffd9f46a9 <unknown>
#5 0x5b8ffd9d6673 <unknown>
#6 0x5b8ffd9a4473 <unknown>
#7 0x5b8ffd9a547e <unknown>
#8 0x5b8ffdc5b0db <unknown>
#9 0x5b8ffdc5f071 <unknown>
#10 0x5b8ffdc479d5 <unknown>
#11 0x5b8ffdc5fbf2 <unknown>
#12 0x5b8ffdc2cb6f <unknown>
#13 0x5b8ffdc83248 <unknown>
#14 0x5b8ffdc83417 <unknown>
#15 0x5b8ffdc930cc <unknown>
#16 0x7a5be89d539d <unknown>
#17 0x7a5be8a5a49c <unknown>

2024-10-09 12:11:21,306 - ERROR    ->  16 -  1  -  1   - Failed to get population data from land '16102A502000230000QX' with locality 'GARABALLA'
Traceback (most recent call last):
  File "/home/miguel/coding-projects/ScrapingFincasHacienda/scrapingFincasHacienda/INE/ine_population.py", line 71, in get_data
    data = self.__get_population()
           ^^^^^^^^^^^^^^^^^^^^^^^
  File "/home/miguel/coding-projects/ScrapingFincasHacienda/scrapingFincasHacienda/INE/ine_population.py", line 137, in __get_population
    "population_now": population_now,
                      ^^^^^^^^^^^^^^
UnboundLocalError: cannot access local variable 'population_now' where it is not associated with a value
2024-10-09 12:19:42,935 - ERROR    ->  16 -  1  -  1   - Failed to get population data from land '16102A502000230000QX' with locality 'GARABALLA'
Traceback (most recent call last):
  File "/home/miguel/coding-projects/ScrapingFincasHacienda/scrapingFincasHacienda/INE/ine_population.py", line 71, in get_data
    data = self.__get_population()
           ^^^^^^^^^^^^^^^^^^^^^^^
  File "/home/miguel/coding-projects/ScrapingFincasHacienda/scrapingFincasHacienda/INE/ine_population.py", line 137, in __get_population
    "population_now": population_now,
                      ^^^^^^^^^^^^^^
UnboundLocalError: cannot access local variable 'population_now' where it is not associated with a value
2024-10-09 12:28:29,862 - ERROR    ->  16 -  1  -  1   - Failed to get population data from land '16102A502000230000QX' with locality 'GARABALLA'
Traceback (most recent call last):
  File "/home/miguel/coding-projects/ScrapingFincasHacienda/scrapingFincasHacienda/INE/ine_population.py", line 71, in get_data
    data = self.__get_population()
           ^^^^^^^^^^^^^^^^^^^^^^^
  File "/home/miguel/coding-projects/ScrapingFincasHacienda/scrapingFincasHacienda/INE/ine_population.py", line 137, in __get_population
    "population_now": population_now if population_now else None,
                                        ^^^^^^^^^^^^^^
UnboundLocalError: cannot access local variable 'population_now' where it is not associated with a value
2024-10-09 21:45:24,884 - ERROR    ->  16 -  1  -  1   - Failed to get 'cp, province, locality'.
Traceback (most recent call last):
  File "/home/miguel/coding-projects/ScrapingFincasHacienda/env/lib/python3.12/site-packages/urllib3/connectionpool.py", line 793, in urlopen
    response = self._make_request(
               ^^^^^^^^^^^^^^^^^^^
  File "/home/miguel/coding-projects/ScrapingFincasHacienda/env/lib/python3.12/site-packages/urllib3/connectionpool.py", line 537, in _make_request
    response = conn.getresponse()
               ^^^^^^^^^^^^^^^^^^
  File "/home/miguel/coding-projects/ScrapingFincasHacienda/env/lib/python3.12/site-packages/urllib3/connection.py", line 466, in getresponse
    httplib_response = super().getresponse()
                       ^^^^^^^^^^^^^^^^^^^^^
  File "/usr/lib/python3.12/http/client.py", line 1428, in getresponse
    response.begin()
  File "/usr/lib/python3.12/http/client.py", line 331, in begin
    version, status, reason = self._read_status()
                              ^^^^^^^^^^^^^^^^^^^
  File "/usr/lib/python3.12/http/client.py", line 300, in _read_status
    raise RemoteDisconnected("Remote end closed connection without"
http.client.RemoteDisconnected: Remote end closed connection without response

During handling of the above exception, another exception occurred:

Traceback (most recent call last):
  File "/home/miguel/coding-projects/ScrapingFincasHacienda/scrapingFincasHacienda/Correos/correos.py", line 63, in get_data
    data = self.__get_info_about_search()
           ^^^^^^^^^^^^^^^^^^^^^^^^^^^^^^
  File "/home/miguel/coding-projects/ScrapingFincasHacienda/scrapingFincasHacienda/Correos/correos.py", line 122, in __get_info_about_search
    cp, province, locality = self.find_elements(
                             ^^^^^^^^^^^^^^^^^^^
  File "/home/miguel/coding-projects/ScrapingFincasHacienda/env/lib/python3.12/site-packages/selenium/webdriver/remote/webdriver.py", line 778, in find_elements
    return self.execute(Command.FIND_ELEMENTS, {"using": by, "value": value})["value"] or []
           ^^^^^^^^^^^^^^^^^^^^^^^^^^^^^^^^^^^^^^^^^^^^^^^^^^^^^^^^^^^^^^^^^^
  File "/home/miguel/coding-projects/ScrapingFincasHacienda/env/lib/python3.12/site-packages/selenium/webdriver/remote/webdriver.py", line 352, in execute
    response = self.command_executor.execute(driver_command, params)
               ^^^^^^^^^^^^^^^^^^^^^^^^^^^^^^^^^^^^^^^^^^^^^^^^^^^^^
  File "/home/miguel/coding-projects/ScrapingFincasHacienda/env/lib/python3.12/site-packages/selenium/webdriver/remote/remote_connection.py", line 306, in execute
    return self._request(command_info[0], url, body=data)
           ^^^^^^^^^^^^^^^^^^^^^^^^^^^^^^^^^^^^^^^^^^^^^^
  File "/home/miguel/coding-projects/ScrapingFincasHacienda/env/lib/python3.12/site-packages/selenium/webdriver/remote/remote_connection.py", line 326, in _request
    response = self._conn.request(method, url, body=body, headers=headers)
               ^^^^^^^^^^^^^^^^^^^^^^^^^^^^^^^^^^^^^^^^^^^^^^^^^^^^^^^^^^^
  File "/home/miguel/coding-projects/ScrapingFincasHacienda/env/lib/python3.12/site-packages/urllib3/_request_methods.py", line 144, in request
    return self.request_encode_body(
           ^^^^^^^^^^^^^^^^^^^^^^^^^
  File "/home/miguel/coding-projects/ScrapingFincasHacienda/env/lib/python3.12/site-packages/urllib3/_request_methods.py", line 279, in request_encode_body
    return self.urlopen(method, url, **extra_kw)
           ^^^^^^^^^^^^^^^^^^^^^^^^^^^^^^^^^^^^^
  File "/home/miguel/coding-projects/ScrapingFincasHacienda/env/lib/python3.12/site-packages/urllib3/poolmanager.py", line 444, in urlopen
    response = conn.urlopen(method, u.request_uri, **kw)
               ^^^^^^^^^^^^^^^^^^^^^^^^^^^^^^^^^^^^^^^^^
  File "/home/miguel/coding-projects/ScrapingFincasHacienda/env/lib/python3.12/site-packages/urllib3/connectionpool.py", line 847, in urlopen
    retries = retries.increment(
              ^^^^^^^^^^^^^^^^^^
  File "/home/miguel/coding-projects/ScrapingFincasHacienda/env/lib/python3.12/site-packages/urllib3/util/retry.py", line 470, in increment
    raise reraise(type(error), error, _stacktrace)
          ^^^^^^^^^^^^^^^^^^^^^^^^^^^^^^^^^^^^^^^^
  File "/home/miguel/coding-projects/ScrapingFincasHacienda/env/lib/python3.12/site-packages/urllib3/util/util.py", line 38, in reraise
    raise value.with_traceback(tb)
  File "/home/miguel/coding-projects/ScrapingFincasHacienda/env/lib/python3.12/site-packages/urllib3/connectionpool.py", line 793, in urlopen
    response = self._make_request(
               ^^^^^^^^^^^^^^^^^^^
  File "/home/miguel/coding-projects/ScrapingFincasHacienda/env/lib/python3.12/site-packages/urllib3/connectionpool.py", line 537, in _make_request
    response = conn.getresponse()
               ^^^^^^^^^^^^^^^^^^
  File "/home/miguel/coding-projects/ScrapingFincasHacienda/env/lib/python3.12/site-packages/urllib3/connection.py", line 466, in getresponse
    httplib_response = super().getresponse()
                       ^^^^^^^^^^^^^^^^^^^^^
  File "/usr/lib/python3.12/http/client.py", line 1428, in getresponse
    response.begin()
  File "/usr/lib/python3.12/http/client.py", line 331, in begin
    version, status, reason = self._read_status()
                              ^^^^^^^^^^^^^^^^^^^
  File "/usr/lib/python3.12/http/client.py", line 300, in _read_status
    raise RemoteDisconnected("Remote end closed connection without"
urllib3.exceptions.ProtocolError: ('Connection aborted.', RemoteDisconnected('Remote end closed connection without response'))
