2024-10-10 14:28:14,308 - ERROR    ->  16 -  1  -  1   - Failed to get data from land '16102A502000230000QX'
Traceback (most recent call last):
  File "/home/miguel/coding-projects/ScrapingFincasHacienda/scrapingFincasHacienda/Catastro/catastro.py", line 81, in get_data
    self.__search()
  File "/home/miguel/coding-projects/ScrapingFincasHacienda/scrapingFincasHacienda/Catastro/catastro.py", line 132, in __search
    self.__close_cookies()
  File "/home/miguel/coding-projects/ScrapingFincasHacienda/scrapingFincasHacienda/Catastro/catastro.py", line 297, in __close_cookies
    button_cookie = self.find_element(
                    ^^^^^^^^^^^^^^^^^^
  File "/home/miguel/coding-projects/ScrapingFincasHacienda/env/lib/python3.12/site-packages/selenium/webdriver/remote/webdriver.py", line 748, in find_element
    return self.execute(Command.FIND_ELEMENT, {"using": by, "value": value})["value"]
           ^^^^^^^^^^^^^^^^^^^^^^^^^^^^^^^^^^^^^^^^^^^^^^^^^^^^^^^^^^^^^^^^^
  File "/home/miguel/coding-projects/ScrapingFincasHacienda/env/lib/python3.12/site-packages/selenium/webdriver/remote/webdriver.py", line 354, in execute
    self.error_handler.check_response(response)
  File "/home/miguel/coding-projects/ScrapingFincasHacienda/env/lib/python3.12/site-packages/selenium/webdriver/remote/errorhandler.py", line 229, in check_response
    raise exception_class(message, screen, stacktrace)
selenium.common.exceptions.NoSuchElementException: Message: no such element: Unable to locate element: {"method":"xpath","selector":"//a[@aria-label='allow cookies']"}
  (Session info: chrome=128.0.6613.113); For documentation on this error, please visit: https://www.selenium.dev/documentation/webdriver/troubleshooting/errors#no-such-element-exception
Stacktrace:
#0 0x61f9a684a2da <unknown>
#1 0x61f9a6518200 <unknown>
#2 0x61f9a6567aa2 <unknown>
#3 0x61f9a6567d41 <unknown>
#4 0x61f9a65ad964 <unknown>
#5 0x61f9a658c8fd <unknown>
#6 0x61f9a65aadfd <unknown>
#7 0x61f9a658c673 <unknown>
#8 0x61f9a655a473 <unknown>
#9 0x61f9a655b47e <unknown>
#10 0x61f9a68110db <unknown>
#11 0x61f9a6815071 <unknown>
#12 0x61f9a67fd9d5 <unknown>
#13 0x61f9a6815bf2 <unknown>
#14 0x61f9a67e2b6f <unknown>
#15 0x61f9a6839248 <unknown>
#16 0x61f9a6839417 <unknown>
#17 0x61f9a68490cc <unknown>
#18 0x77ce89ea139d <unknown>
#19 0x77ce89f2649c <unknown>

2024-10-10 14:28:27,987 - ERROR    ->  16 -  2  -  1   - Failed to get data from land '16102A502000490000QK'
Traceback (most recent call last):
  File "/home/miguel/coding-projects/ScrapingFincasHacienda/env/lib/python3.12/site-packages/urllib3/connectionpool.py", line 793, in urlopen
    response = self._make_request(
               ^^^^^^^^^^^^^^^^^^^
  File "/home/miguel/coding-projects/ScrapingFincasHacienda/env/lib/python3.12/site-packages/urllib3/connectionpool.py", line 537, in _make_request
    response = conn.getresponse()
               ^^^^^^^^^^^^^^^^^^
  File "/home/miguel/coding-projects/ScrapingFincasHacienda/env/lib/python3.12/site-packages/urllib3/connection.py", line 466, in getresponse
    httplib_response = super().getresponse()
                       ^^^^^^^^^^^^^^^^^^^^^
  File "/usr/lib/python3.12/http/client.py", line 1428, in getresponse
    response.begin()
  File "/usr/lib/python3.12/http/client.py", line 331, in begin
    version, status, reason = self._read_status()
                              ^^^^^^^^^^^^^^^^^^^
  File "/usr/lib/python3.12/http/client.py", line 300, in _read_status
    raise RemoteDisconnected("Remote end closed connection without"
http.client.RemoteDisconnected: Remote end closed connection without response

During handling of the above exception, another exception occurred:

Traceback (most recent call last):
  File "/home/miguel/coding-projects/ScrapingFincasHacienda/scrapingFincasHacienda/Catastro/catastro.py", line 81, in get_data
    self.__search()
  File "/home/miguel/coding-projects/ScrapingFincasHacienda/scrapingFincasHacienda/Catastro/catastro.py", line 132, in __search
    self.__close_cookies()
  File "/home/miguel/coding-projects/ScrapingFincasHacienda/scrapingFincasHacienda/Catastro/catastro.py", line 297, in __close_cookies
    button_cookie = self.find_element(
                    ^^^^^^^^^^^^^^^^^^
  File "/home/miguel/coding-projects/ScrapingFincasHacienda/env/lib/python3.12/site-packages/selenium/webdriver/remote/webdriver.py", line 748, in find_element
    return self.execute(Command.FIND_ELEMENT, {"using": by, "value": value})["value"]
           ^^^^^^^^^^^^^^^^^^^^^^^^^^^^^^^^^^^^^^^^^^^^^^^^^^^^^^^^^^^^^^^^^
  File "/home/miguel/coding-projects/ScrapingFincasHacienda/env/lib/python3.12/site-packages/selenium/webdriver/remote/webdriver.py", line 352, in execute
    response = self.command_executor.execute(driver_command, params)
               ^^^^^^^^^^^^^^^^^^^^^^^^^^^^^^^^^^^^^^^^^^^^^^^^^^^^^
  File "/home/miguel/coding-projects/ScrapingFincasHacienda/env/lib/python3.12/site-packages/selenium/webdriver/remote/remote_connection.py", line 306, in execute
    return self._request(command_info[0], url, body=data)
           ^^^^^^^^^^^^^^^^^^^^^^^^^^^^^^^^^^^^^^^^^^^^^^
  File "/home/miguel/coding-projects/ScrapingFincasHacienda/env/lib/python3.12/site-packages/selenium/webdriver/remote/remote_connection.py", line 326, in _request
    response = self._conn.request(method, url, body=body, headers=headers)
               ^^^^^^^^^^^^^^^^^^^^^^^^^^^^^^^^^^^^^^^^^^^^^^^^^^^^^^^^^^^
  File "/home/miguel/coding-projects/ScrapingFincasHacienda/env/lib/python3.12/site-packages/urllib3/_request_methods.py", line 144, in request
    return self.request_encode_body(
           ^^^^^^^^^^^^^^^^^^^^^^^^^
  File "/home/miguel/coding-projects/ScrapingFincasHacienda/env/lib/python3.12/site-packages/urllib3/_request_methods.py", line 279, in request_encode_body
    return self.urlopen(method, url, **extra_kw)
           ^^^^^^^^^^^^^^^^^^^^^^^^^^^^^^^^^^^^^
  File "/home/miguel/coding-projects/ScrapingFincasHacienda/env/lib/python3.12/site-packages/urllib3/poolmanager.py", line 444, in urlopen
    response = conn.urlopen(method, u.request_uri, **kw)
               ^^^^^^^^^^^^^^^^^^^^^^^^^^^^^^^^^^^^^^^^^
  File "/home/miguel/coding-projects/ScrapingFincasHacienda/env/lib/python3.12/site-packages/urllib3/connectionpool.py", line 847, in urlopen
    retries = retries.increment(
              ^^^^^^^^^^^^^^^^^^
  File "/home/miguel/coding-projects/ScrapingFincasHacienda/env/lib/python3.12/site-packages/urllib3/util/retry.py", line 470, in increment
    raise reraise(type(error), error, _stacktrace)
          ^^^^^^^^^^^^^^^^^^^^^^^^^^^^^^^^^^^^^^^^
  File "/home/miguel/coding-projects/ScrapingFincasHacienda/env/lib/python3.12/site-packages/urllib3/util/util.py", line 38, in reraise
    raise value.with_traceback(tb)
  File "/home/miguel/coding-projects/ScrapingFincasHacienda/env/lib/python3.12/site-packages/urllib3/connectionpool.py", line 793, in urlopen
    response = self._make_request(
               ^^^^^^^^^^^^^^^^^^^
  File "/home/miguel/coding-projects/ScrapingFincasHacienda/env/lib/python3.12/site-packages/urllib3/connectionpool.py", line 537, in _make_request
    response = conn.getresponse()
               ^^^^^^^^^^^^^^^^^^
  File "/home/miguel/coding-projects/ScrapingFincasHacienda/env/lib/python3.12/site-packages/urllib3/connection.py", line 466, in getresponse
    httplib_response = super().getresponse()
                       ^^^^^^^^^^^^^^^^^^^^^
  File "/usr/lib/python3.12/http/client.py", line 1428, in getresponse
    response.begin()
  File "/usr/lib/python3.12/http/client.py", line 331, in begin
    version, status, reason = self._read_status()
                              ^^^^^^^^^^^^^^^^^^^
  File "/usr/lib/python3.12/http/client.py", line 300, in _read_status
    raise RemoteDisconnected("Remote end closed connection without"
urllib3.exceptions.ProtocolError: ('Connection aborted.', RemoteDisconnected('Remote end closed connection without response'))
2024-10-10 14:28:30,464 - ERROR    ->  16 -  3  -  1   - Failed to get data from land '16102A502000960000QU'
Traceback (most recent call last):
  File "/home/miguel/coding-projects/ScrapingFincasHacienda/scrapingFincasHacienda/Catastro/catastro.py", line 81, in get_data
    self.__search()
  File "/home/miguel/coding-projects/ScrapingFincasHacienda/scrapingFincasHacienda/Catastro/catastro.py", line 132, in __search
    self.__close_cookies()
  File "/home/miguel/coding-projects/ScrapingFincasHacienda/scrapingFincasHacienda/Catastro/catastro.py", line 297, in __close_cookies
    button_cookie = self.find_element(
                    ^^^^^^^^^^^^^^^^^^
  File "/home/miguel/coding-projects/ScrapingFincasHacienda/env/lib/python3.12/site-packages/selenium/webdriver/remote/webdriver.py", line 748, in find_element
    return self.execute(Command.FIND_ELEMENT, {"using": by, "value": value})["value"]
           ^^^^^^^^^^^^^^^^^^^^^^^^^^^^^^^^^^^^^^^^^^^^^^^^^^^^^^^^^^^^^^^^^
  File "/home/miguel/coding-projects/ScrapingFincasHacienda/env/lib/python3.12/site-packages/selenium/webdriver/remote/webdriver.py", line 354, in execute
    self.error_handler.check_response(response)
  File "/home/miguel/coding-projects/ScrapingFincasHacienda/env/lib/python3.12/site-packages/selenium/webdriver/remote/errorhandler.py", line 229, in check_response
    raise exception_class(message, screen, stacktrace)
selenium.common.exceptions.WebDriverException: Message: disconnected: unable to send message to renderer
  (failed to check if window was closed: disconnected: not connected to DevTools)
  (Session info: chrome=128.0.6613.113)
Stacktrace:
#0 0x5b44445472da <unknown>
#1 0x5b4444215200 <unknown>
#2 0x5b44441fc257 <unknown>
#3 0x5b44441fc1d5 <unknown>
#4 0x5b44441fa9ba <unknown>
#5 0x5b44441fb6bf <unknown>
#6 0x5b4444218e75 <unknown>
#7 0x5b44442197b0 <unknown>
#8 0x5b444421cd15 <unknown>
#9 0x5b444421cd9c <unknown>
#10 0x5b44442646fc <unknown>
#11 0x5b4444264d41 <unknown>
#12 0x5b44442aa964 <unknown>
#13 0x5b44442898fd <unknown>
#14 0x5b44442a7dfd <unknown>
#15 0x5b4444289673 <unknown>
#16 0x5b4444257473 <unknown>
#17 0x5b444425847e <unknown>
#18 0x5b444450e0db <unknown>
#19 0x5b4444512071 <unknown>
#20 0x5b44444fa9d5 <unknown>
#21 0x5b4444512bf2 <unknown>
#22 0x5b44444dfb6f <unknown>
#23 0x5b4444536248 <unknown>
#24 0x5b4444536417 <unknown>
#25 0x5b44445460cc <unknown>
#26 0x71f8a7f4139d <unknown>
#27 0x71f8a7fc649c <unknown>

2024-10-10 14:28:32,651 - ERROR    ->  16 -  4  -  1   - Failed to get data from land '16102A503000010000QI'
Traceback (most recent call last):
  File "/home/miguel/coding-projects/ScrapingFincasHacienda/env/lib/python3.12/site-packages/urllib3/connectionpool.py", line 793, in urlopen
    response = self._make_request(
               ^^^^^^^^^^^^^^^^^^^
  File "/home/miguel/coding-projects/ScrapingFincasHacienda/env/lib/python3.12/site-packages/urllib3/connectionpool.py", line 537, in _make_request
    response = conn.getresponse()
               ^^^^^^^^^^^^^^^^^^
  File "/home/miguel/coding-projects/ScrapingFincasHacienda/env/lib/python3.12/site-packages/urllib3/connection.py", line 466, in getresponse
    httplib_response = super().getresponse()
                       ^^^^^^^^^^^^^^^^^^^^^
  File "/usr/lib/python3.12/http/client.py", line 1428, in getresponse
    response.begin()
  File "/usr/lib/python3.12/http/client.py", line 331, in begin
    version, status, reason = self._read_status()
                              ^^^^^^^^^^^^^^^^^^^
  File "/usr/lib/python3.12/http/client.py", line 300, in _read_status
    raise RemoteDisconnected("Remote end closed connection without"
http.client.RemoteDisconnected: Remote end closed connection without response

During handling of the above exception, another exception occurred:

Traceback (most recent call last):
  File "/home/miguel/coding-projects/ScrapingFincasHacienda/scrapingFincasHacienda/Catastro/catastro.py", line 81, in get_data
    self.__search()
  File "/home/miguel/coding-projects/ScrapingFincasHacienda/scrapingFincasHacienda/Catastro/catastro.py", line 132, in __search
    self.__close_cookies()
  File "/home/miguel/coding-projects/ScrapingFincasHacienda/scrapingFincasHacienda/Catastro/catastro.py", line 297, in __close_cookies
    button_cookie = self.find_element(
                    ^^^^^^^^^^^^^^^^^^
  File "/home/miguel/coding-projects/ScrapingFincasHacienda/env/lib/python3.12/site-packages/selenium/webdriver/remote/webdriver.py", line 748, in find_element
    return self.execute(Command.FIND_ELEMENT, {"using": by, "value": value})["value"]
           ^^^^^^^^^^^^^^^^^^^^^^^^^^^^^^^^^^^^^^^^^^^^^^^^^^^^^^^^^^^^^^^^^
  File "/home/miguel/coding-projects/ScrapingFincasHacienda/env/lib/python3.12/site-packages/selenium/webdriver/remote/webdriver.py", line 352, in execute
    response = self.command_executor.execute(driver_command, params)
               ^^^^^^^^^^^^^^^^^^^^^^^^^^^^^^^^^^^^^^^^^^^^^^^^^^^^^
  File "/home/miguel/coding-projects/ScrapingFincasHacienda/env/lib/python3.12/site-packages/selenium/webdriver/remote/remote_connection.py", line 306, in execute
    return self._request(command_info[0], url, body=data)
           ^^^^^^^^^^^^^^^^^^^^^^^^^^^^^^^^^^^^^^^^^^^^^^
  File "/home/miguel/coding-projects/ScrapingFincasHacienda/env/lib/python3.12/site-packages/selenium/webdriver/remote/remote_connection.py", line 326, in _request
    response = self._conn.request(method, url, body=body, headers=headers)
               ^^^^^^^^^^^^^^^^^^^^^^^^^^^^^^^^^^^^^^^^^^^^^^^^^^^^^^^^^^^
  File "/home/miguel/coding-projects/ScrapingFincasHacienda/env/lib/python3.12/site-packages/urllib3/_request_methods.py", line 144, in request
    return self.request_encode_body(
           ^^^^^^^^^^^^^^^^^^^^^^^^^
  File "/home/miguel/coding-projects/ScrapingFincasHacienda/env/lib/python3.12/site-packages/urllib3/_request_methods.py", line 279, in request_encode_body
    return self.urlopen(method, url, **extra_kw)
           ^^^^^^^^^^^^^^^^^^^^^^^^^^^^^^^^^^^^^
  File "/home/miguel/coding-projects/ScrapingFincasHacienda/env/lib/python3.12/site-packages/urllib3/poolmanager.py", line 444, in urlopen
    response = conn.urlopen(method, u.request_uri, **kw)
               ^^^^^^^^^^^^^^^^^^^^^^^^^^^^^^^^^^^^^^^^^
  File "/home/miguel/coding-projects/ScrapingFincasHacienda/env/lib/python3.12/site-packages/urllib3/connectionpool.py", line 847, in urlopen
    retries = retries.increment(
              ^^^^^^^^^^^^^^^^^^
  File "/home/miguel/coding-projects/ScrapingFincasHacienda/env/lib/python3.12/site-packages/urllib3/util/retry.py", line 470, in increment
    raise reraise(type(error), error, _stacktrace)
          ^^^^^^^^^^^^^^^^^^^^^^^^^^^^^^^^^^^^^^^^
  File "/home/miguel/coding-projects/ScrapingFincasHacienda/env/lib/python3.12/site-packages/urllib3/util/util.py", line 38, in reraise
    raise value.with_traceback(tb)
  File "/home/miguel/coding-projects/ScrapingFincasHacienda/env/lib/python3.12/site-packages/urllib3/connectionpool.py", line 793, in urlopen
    response = self._make_request(
               ^^^^^^^^^^^^^^^^^^^
  File "/home/miguel/coding-projects/ScrapingFincasHacienda/env/lib/python3.12/site-packages/urllib3/connectionpool.py", line 537, in _make_request
    response = conn.getresponse()
               ^^^^^^^^^^^^^^^^^^
  File "/home/miguel/coding-projects/ScrapingFincasHacienda/env/lib/python3.12/site-packages/urllib3/connection.py", line 466, in getresponse
    httplib_response = super().getresponse()
                       ^^^^^^^^^^^^^^^^^^^^^
  File "/usr/lib/python3.12/http/client.py", line 1428, in getresponse
    response.begin()
  File "/usr/lib/python3.12/http/client.py", line 331, in begin
    version, status, reason = self._read_status()
                              ^^^^^^^^^^^^^^^^^^^
  File "/usr/lib/python3.12/http/client.py", line 300, in _read_status
    raise RemoteDisconnected("Remote end closed connection without"
urllib3.exceptions.ProtocolError: ('Connection aborted.', RemoteDisconnected('Remote end closed connection without response'))
2024-10-10 14:28:34,796 - ERROR    ->  16 -  5  -  1   - Failed to get data from land '16102A503000190000QT'
Traceback (most recent call last):
  File "/home/miguel/coding-projects/ScrapingFincasHacienda/scrapingFincasHacienda/Catastro/catastro.py", line 81, in get_data
    self.__search()
  File "/home/miguel/coding-projects/ScrapingFincasHacienda/scrapingFincasHacienda/Catastro/catastro.py", line 132, in __search
    self.__close_cookies()
  File "/home/miguel/coding-projects/ScrapingFincasHacienda/scrapingFincasHacienda/Catastro/catastro.py", line 297, in __close_cookies
    button_cookie = self.find_element(
                    ^^^^^^^^^^^^^^^^^^
  File "/home/miguel/coding-projects/ScrapingFincasHacienda/env/lib/python3.12/site-packages/selenium/webdriver/remote/webdriver.py", line 748, in find_element
    return self.execute(Command.FIND_ELEMENT, {"using": by, "value": value})["value"]
           ^^^^^^^^^^^^^^^^^^^^^^^^^^^^^^^^^^^^^^^^^^^^^^^^^^^^^^^^^^^^^^^^^
  File "/home/miguel/coding-projects/ScrapingFincasHacienda/env/lib/python3.12/site-packages/selenium/webdriver/remote/webdriver.py", line 354, in execute
    self.error_handler.check_response(response)
  File "/home/miguel/coding-projects/ScrapingFincasHacienda/env/lib/python3.12/site-packages/selenium/webdriver/remote/errorhandler.py", line 229, in check_response
    raise exception_class(message, screen, stacktrace)
selenium.common.exceptions.WebDriverException: Message: disconnected: unable to send message to renderer
  (failed to check if window was closed: disconnected: not connected to DevTools)
  (Session info: chrome=128.0.6613.113)
Stacktrace:
#0 0x5bc268c862da <unknown>
#1 0x5bc268954200 <unknown>
#2 0x5bc26893b257 <unknown>
#3 0x5bc26893b1d5 <unknown>
#4 0x5bc2689399ba <unknown>
#5 0x5bc26893a6bf <unknown>
#6 0x5bc268957e75 <unknown>
#7 0x5bc2689587b0 <unknown>
#8 0x5bc26895bd15 <unknown>
#9 0x5bc26895bd9c <unknown>
#10 0x5bc2689a36fc <unknown>
#11 0x5bc2689a3d41 <unknown>
#12 0x5bc2689e9964 <unknown>
#13 0x5bc2689c88fd <unknown>
#14 0x5bc2689e6dfd <unknown>
#15 0x5bc2689c8673 <unknown>
#16 0x5bc268996473 <unknown>
#17 0x5bc26899747e <unknown>
#18 0x5bc268c4d0db <unknown>
#19 0x5bc268c51071 <unknown>
#20 0x5bc268c399d5 <unknown>
#21 0x5bc268c51bf2 <unknown>
#22 0x5bc268c1eb6f <unknown>
#23 0x5bc268c75248 <unknown>
#24 0x5bc268c75417 <unknown>
#25 0x5bc268c850cc <unknown>
#26 0x714348d5739d <unknown>
#27 0x714348ddc49c <unknown>

